Workbook

Sheet Summary
B2: Foreign Outflows, Domestic Inflows and the Indian Equity Market
B3: FPI and DII equity flows, SIP growth and macro conditions, January 2017 to September 2026 (117 monthly observations)
B4: Status: preliminary. FPI and DII series are from different sources and are being rebuilt on one NSE basis. October 2026 excluded as a partial month.
B6: Complete months analysed | F6: FPI-selling months fully offset | J6: Growth in monthly SIP contributions
B7: =COUNT('Monthly Data'!$A$5:$A$121) -> 117 | F7: ='Offset Analysis'!B10 -> 0.79245283 | J7: ='Monthly Data'!L121/'Monthly Data'!L5 -> 7.9340659
B8: Jan 2017 to Sep 2026 | F8: ='Offset Analysis'!B7&" of "&'Offset Analysis'!B6&" months" -> 42 of 53 months | J8: ₹4,095 cr to ₹32,490 cr
B10: Key findings
B11: Domestic buying usually covers foreign selling | F11: DII buying exceeded FPI selling in 42 of 53 selling months, and in 18 of 19 since 2024.
B12: Offsetting does not mean a rising market | F12: Fully offset months still averaged a -1.33% Nifty return, against +2.61% in months without FPI selling.
B13: Large outflows are harder to absorb | F13: In the ten biggest outflow months, 6 were fully offset and the average Nifty return was -3.95%.
B14: The domestic savings base has grown about eightfold | F14: Monthly SIPs rose from ₹4,095 cr to ₹32,490 cr; equity mutual fund AUM rose about sevenfold.
B15: The rupee is the macro variable that matters most | F15: USD/INR monthly change correlates -0.52 with Nifty returns; repo rate and CPI show almost none.
B17: Charts
B50: Source: NSDL, Trendlyne, NSE, AMFI, RBI. Detailed method and limitations are on the Method & Sources tab.

Sheet Findings
A1: Research findings
A2: Figures are preliminary (see status note on Summary). Live values are on the Offset Analysis and Correlations tabs.
A4: # | B4: Question | C4: Result | D4: Reading | E4: Limitation
A5: 1 | B5: Do domestic institutions absorb foreign selling? | C5: FPI was a net seller in 53 of 117 complete months. DII buying exceeded the selling in 42 of them (79%). Since January 2024 the figure is 18 of 19. | D5: Domestic buying has regularly been large enough to cover foreign selling, and more so in recent years. | E5: Net monthly flows only. Says nothing about intra-month timing, and FPI and DII data are not yet from one source.
A6: 2 | B6: Does offsetting protect the market? | C6: Average Nifty return in FPI-selling months was -1.08%. Fully offset months averaged -1.33%; months not fully offset averaged -0.16%; months without FPI selling averaged +2.61%. | D6: Offsetting did not coincide with positive returns. Domestic buying absorbs selling but does not prevent weak months. | E6: Group averages are not causal. Whatever drives foreign selling may also drive domestic buying and returns.
A7: 3 | B7: Are the largest outflow months harder to offset? | C7: Of the ten largest FPI-selling months, 6 were fully offset and the average Nifty return was -3.95%. Across the other 43 selling months, 84% were fully offset and the average return was -0.39%. | D7: Offset rate falls and returns weaken when foreign selling is very large. | E7: Ten observations. Treat as indicative.
A8: 4 | B8: Is the domestic savings base growing? | C8: Monthly SIP contributions rose from ₹4,095 crore (Jan 2017) to ₹32,490 crore (Sep 2026), about 7.9 times. Equity mutual fund AUM rose from ₹5.4 lakh crore (Mar 2017) to ₹37.9 lakh crore (Jun 2026), about 7 times. | D8: Retail participation through SIPs has expanded steadily, which supports the case for a larger domestic buffer. | E8: AUM growth includes market appreciation. SIP figures are gross contributions, not net equity purchases.
A9: 5 | B9: Is SIP growth linked to offsetting? | C9: Across FPI-selling months, the correlation between SIP level and full offset is +0.26; with the offset ratio it is -0.04. | D9: SIP growth is modestly associated with the chance of a full offset but not with its size. | E9: Both series trend upward over time, so the link may reflect time rather than a direct relationship.
A10: 6 | B10: How do flows relate to returns? | C10: Same-month correlation with Nifty return: FPI +0.53, DII -0.47, combined +0.07. | D10: Foreign flows move with the market. Domestic flows move against it, consistent with buying into weakness. | E10: Contemporaneous correlation. Direction of cause is not established.
A11: 7 | B11: Do macro variables matter? | C11: USD/INR monthly change vs Nifty return: r = -0.52 (107 months), -0.37 after trimming extremes, and between -0.39 and -0.66 in each sub-period. Repo rate (-0.06) and CPI (+0.03) show almost no relationship with returns. | D11: Rupee weakness is the macro variable most consistently associated with weak equity months in this sample. | E11: Association only. The rupee and equity prices respond to common drivers such as global risk sentiment.

Sheet Offset Analysis
A1: Offset analysis: do domestic institutions absorb foreign selling?
A2: Complete months only (Jan 2017 to Sep 2026). A month is 'fully offset' when DII net buying is at least as large as FPI net selling. Flow series are preliminary; see Method & Sources.
A4: 1. Nifty returns by flow regime
A5: Regime | B5: Months | C5: Mean Nifty return | D5: Months with positive return | E5: Avg FPI flow (₹ cr) | F5: Avg DII flow (₹ cr)
A6: FPI net sellers (all) | B6: =COUNTIF('Monthly Data'!$G$5:$G$121,"Yes") -> 53 | C6: =AVERAGEIFS('Monthly Data'!$K$5:$K$121,'Monthly Data'!$G$5:$G$121,"Yes") -> -0.010780589 | D6: =COUNTIFS('Monthly Data'!$G$5:$G$121,"Yes",'Monthly Data'!$K$5:$K$121,">0")/COUNTIFS('Monthly Data'!$G$5:$G$121,"Yes",'Monthly Data'!$K$5:$K$121,">-1") -> 0.30769231 | E6: =AVERAGEIFS('Monthly Data'!$D$5:$D$121,'Monthly Data'!$G$5:$G$121,"Yes") -> -24577.132 | F6: =AVERAGEIFS('Monthly Data'!$E$5:$E$121,'Monthly Data'!$G$5:$G$121,"Yes") -> 38698.892
A7: of which fully offset by DII | B7: =COUNTIF('Monthly Data'!$H$5:$H$121,"Yes") -> 42 | C7: =AVERAGEIFS('Monthly Data'!$K$5:$K$121,'Monthly Data'!$H$5:$H$121,"Yes") -> -0.013251138 | D7: =COUNTIFS('Monthly Data'!$H$5:$H$121,"Yes",'Monthly Data'!$K$5:$K$121,">0")/COUNTIFS('Monthly Data'!$H$5:$H$121,"Yes",'Monthly Data'!$K$5:$K$121,">-1") -> 0.26829268 | E7: =AVERAGEIFS('Monthly Data'!$D$5:$D$121,'Monthly Data'!$H$5:$H$121,"Yes") -> -23590.119 | F7: =AVERAGEIFS('Monthly Data'!$E$5:$E$121,'Monthly Data'!$H$5:$H$121,"Yes") -> 42892.031
A8: of which not fully offset | B8: =COUNTIF('Monthly Data'!$H$5:$H$121,"No") -> 11 | C8: =AVERAGEIFS('Monthly Data'!$K$5:$K$121,'Monthly Data'!$H$5:$H$121,"No") -> -0.0015721774 | D8: =COUNTIFS('Monthly Data'!$H$5:$H$121,"No",'Monthly Data'!$K$5:$K$121,">0")/COUNTIFS('Monthly Data'!$H$5:$H$121,"No",'Monthly Data'!$K$5:$K$121,">-1") -> 0.45454545 | E8: =AVERAGEIFS('Monthly Data'!$D$5:$D$121,'Monthly Data'!$H$5:$H$121,"No") -> -28345.727 | F8: =AVERAGEIFS('Monthly Data'!$E$5:$E$121,'Monthly Data'!$H$5:$H$121,"No") -> 22688.727
A9: FPI not selling | B9: =COUNTIF('Monthly Data'!$G$5:$G$121,"No") -> 64 | C9: =AVERAGEIFS('Monthly Data'!$K$5:$K$121,'Monthly Data'!$G$5:$G$121,"No") -> 0.026080691 | D9: =COUNTIFS('Monthly Data'!$G$5:$G$121,"No",'Monthly Data'!$K$5:$K$121,">0")/COUNTIFS('Monthly Data'!$G$5:$G$121,"No",'Monthly Data'!$K$5:$K$121,">-1") -> 0.765625 | E9: =AVERAGEIFS('Monthly Data'!$D$5:$D$121,'Monthly Data'!$G$5:$G$121,"No") -> 19397.953 | F9: =AVERAGEIFS('Monthly Data'!$E$5:$E$121,'Monthly Data'!$G$5:$G$121,"No") -> 10416.261
A10: Full-offset rate (fully offset ÷ FPI-selling months) | B10: =B7/B6 -> 0.79245283
A11: January 2017 counts as a selling month but has no return (December 2016 close not in the dataset), so averages in column C use 52 observations.
A13: 2. Offset rate by period
A14: Period | B14: FPI-selling months | C14: Fully offset | D14: Offset rate | E14: Total months | F14: Selling months as share of period
A15: 2017 to 2019 | B15: =COUNTIFS('Monthly Data'!$G$5:$G$121,"Yes",'Monthly Data'!$B$5:$B$121,">=2017",'Monthly Data'!$B$5:$B$121,"<=2019") -> 13 | C15: =COUNTIFS('Monthly Data'!$H$5:$H$121,"Yes",'Monthly Data'!$B$5:$B$121,">=2017",'Monthly Data'!$B$5:$B$121,"<=2019") -> 11 | D15: =C15/B15 -> 0.84615385 | E15: =COUNTIFS('Monthly Data'!$B$5:$B$121,">=2017",'Monthly Data'!$B$5:$B$121,"<=2019") -> 36 | F15: =B15/E15 -> 0.36111111
A16: 2020 to 2023 | B16: =COUNTIFS('Monthly Data'!$G$5:$G$121,"Yes",'Monthly Data'!$B$5:$B$121,">=2020",'Monthly Data'!$B$5:$B$121,"<=2023") -> 21 | C16: =COUNTIFS('Monthly Data'!$H$5:$H$121,"Yes",'Monthly Data'!$B$5:$B$121,">=2020",'Monthly Data'!$B$5:$B$121,"<=2023") -> 13 | D16: =C16/B16 -> 0.61904762 | E16: =COUNTIFS('Monthly Data'!$B$5:$B$121,">=2020",'Monthly Data'!$B$5:$B$121,"<=2023") -> 48 | F16: =B16/E16 -> 0.4375
A17: 2024 to Sep 2026 | B17: =COUNTIFS('Monthly Data'!$G$5:$G$121,"Yes",'Monthly Data'!$B$5:$B$121,">=2024",'Monthly Data'!$B$5:$B$121,"<=2026") -> 19 | C17: =COUNTIFS('Monthly Data'!$H$5:$H$121,"Yes",'Monthly Data'!$B$5:$B$121,">=2024",'Monthly Data'!$B$5:$B$121,"<=2026") -> 18 | D17: =C17/B17 -> 0.94736842 | E17: =COUNTIFS('Monthly Data'!$B$5:$B$121,">=2024",'Monthly Data'!$B$5:$B$121,"<=2026") -> 33 | F17: =B17/E17 -> 0.57575758
A20: 3. Stress test: the ten largest monthly FPI outflows
A21: Rank | B21: Month | C21: FPI flow (₹ cr) | D21: DII flow (₹ cr) | E21: Offset ratio | F21: Fully offset? | G21: Nifty return | H21: SIP (₹ cr)
A22: 1 | B22: =INDEX('Monthly Data'!$A$5:$A$121,MATCH(C22,'Monthly Data'!$D$5:$D$121,0)) -> 46082 | C22: =SMALL('Monthly Data'!$D$5:$D$121,A22) -> -117775 | D22: =INDEX('Monthly Data'!$E$5:$E$121,MATCH(C22,'Monthly Data'!$D$5:$D$121,0)) -> 142960.4 | E22: =D22/-C22 -> 1.2138433 | F22: =IF(D22>=-C22,"Yes","No") -> Yes | G22: =INDEX('Monthly Data'!$K$5:$K$121,MATCH(C22,'Monthly Data'!$D$5:$D$121,0)) -> -0.11308192 | H22: =INDEX('Monthly Data'!$L$5:$L$121,MATCH(C22,'Monthly Data'!$D$5:$D$121,0)) -> 32087
A23: 2 | B23: =INDEX('Monthly Data'!$A$5:$A$121,MATCH(C23,'Monthly Data'!$D$5:$D$121,0)) -> 45566 | C23: =SMALL('Monthly Data'!$D$5:$D$121,A23) -> -94017 | D23: =INDEX('Monthly Data'!$E$5:$E$121,MATCH(C23,'Monthly Data'!$D$5:$D$121,0)) -> 107254.7 | E23: =D23/-C23 -> 1.1408011 | F23: =IF(D23>=-C23,"Yes","No") -> Yes | G23: =INDEX('Monthly Data'!$K$5:$K$121,MATCH(C23,'Monthly Data'!$D$5:$D$121,0)) -> -0.062202523 | H23: =INDEX('Monthly Data'!$L$5:$L$121,MATCH(C23,'Monthly Data'!$D$5:$D$121,0)) -> 25323
A24: 3 | B24: =INDEX('Monthly Data'!$A$5:$A$121,MATCH(C24,'Monthly Data'!$D$5:$D$121,0)) -> 45658 | C24: =SMALL('Monthly Data'!$D$5:$D$121,A24) -> -78027 | D24: =INDEX('Monthly Data'!$E$5:$E$121,MATCH(C24,'Monthly Data'!$D$5:$D$121,0)) -> 86591.8 | E24: =D24/-C24 -> 1.1097671 | F24: =IF(D24>=-C24,"Yes","No") -> Yes | G24: =INDEX('Monthly Data'!$K$5:$K$121,MATCH(C24,'Monthly Data'!$D$5:$D$121,0)) -> -0.0057687102 | H24: =INDEX('Monthly Data'!$L$5:$L$121,MATCH(C24,'Monthly Data'!$D$5:$D$121,0)) -> 26400
A25: 4 | B25: =INDEX('Monthly Data'!$A$5:$A$121,MATCH(C25,'Monthly Data'!$D$5:$D$121,0)) -> 43891 | C25: =SMALL('Monthly Data'!$D$5:$D$121,A25) -> -61973 | D25: =INDEX('Monthly Data'!$E$5:$E$121,MATCH(C25,'Monthly Data'!$D$5:$D$121,0)) -> 55595.2 | E25: =D25/-C25 -> 0.89708744 | F25: =IF(D25>=-C25,"Yes","No") -> No | G25: =INDEX('Monthly Data'!$K$5:$K$121,MATCH(C25,'Monthly Data'!$D$5:$D$121,0)) -> -0.23246368 | H25: =INDEX('Monthly Data'!$L$5:$L$121,MATCH(C25,'Monthly Data'!$D$5:$D$121,0)) -> 8641
A26: 5 | B26: =INDEX('Monthly Data'!$A$5:$A$121,MATCH(C26,'Monthly Data'!$D$5:$D$121,0)) -> 46113 | C26: =SMALL('Monthly Data'!$D$5:$D$121,A26) -> -60847 | D26: =INDEX('Monthly Data'!$E$5:$E$121,MATCH(C26,'Monthly Data'!$D$5:$D$121,0)) -> 51063.9 | E26: =D26/-C26 -> 0.83921804 | F26: =IF(D26>=-C26,"Yes","No") -> No | G26: =INDEX('Monthly Data'!$K$5:$K$121,MATCH(C26,'Monthly Data'!$D$5:$D$121,0)) -> 0.07461019 | H26: =INDEX('Monthly Data'!$L$5:$L$121,MATCH(C26,'Monthly Data'!$D$5:$D$121,0)) -> 31115
A27: 6 | B27: =INDEX('Monthly Data'!$A$5:$A$121,MATCH(C27,'Monthly Data'!$D$5:$D$121,0)) -> 44713 | C27: =SMALL('Monthly Data'!$D$5:$D$121,A27) -> -50203 | D27: =INDEX('Monthly Data'!$E$5:$E$121,MATCH(C27,'Monthly Data'!$D$5:$D$121,0)) -> 46599.2 | E27: =D27/-C27 -> 0.92821545 | F27: =IF(D27>=-C27,"Yes","No") -> No | G27: =INDEX('Monthly Data'!$K$5:$K$121,MATCH(C27,'Monthly Data'!$D$5:$D$121,0)) -> -0.048496944 | H27: =INDEX('Monthly Data'!$L$5:$L$121,MATCH(C27,'Monthly Data'!$D$5:$D$121,0)) -> 12276
A28: 7 | B28: =INDEX('Monthly Data'!$A$5:$A$121,MATCH(C28,'Monthly Data'!$D$5:$D$121,0)) -> 46174 | C28: =SMALL('Monthly Data'!$D$5:$D$121,A28) -> -49340 | D28: =INDEX('Monthly Data'!$E$5:$E$121,MATCH(C28,'Monthly Data'!$D$5:$D$121,0)) -> 85800.1 | E28: =D28/-C28 -> 1.7389562 | F28: =IF(D28>=-C28,"Yes","No") -> Yes | G28: =INDEX('Monthly Data'!$K$5:$K$121,MATCH(C28,'Monthly Data'!$D$5:$D$121,0)) -> 0.013504475 | H28: =INDEX('Monthly Data'!$L$5:$L$121,MATCH(C28,'Monthly Data'!$D$5:$D$121,0)) -> 31781
A29: 8 | B29: =INDEX('Monthly Data'!$A$5:$A$121,MATCH(C29,'Monthly Data'!$D$5:$D$121,0)) -> 44621 | C29: =SMALL('Monthly Data'!$D$5:$D$121,A29) -> -41123 | D29: =INDEX('Monthly Data'!$E$5:$E$121,MATCH(C29,'Monthly Data'!$D$5:$D$121,0)) -> 39677 | E29: =D29/-C29 -> 0.9648372 | F29: =IF(D29>=-C29,"Yes","No") -> No | G29: =INDEX('Monthly Data'!$K$5:$K$121,MATCH(C29,'Monthly Data'!$D$5:$D$121,0)) -> 0.039946052 | H29: =INDEX('Monthly Data'!$L$5:$L$121,MATCH(C29,'Monthly Data'!$D$5:$D$121,0)) -> 12328
A30: 9 | B30: =INDEX('Monthly Data'!$A$5:$A$121,MATCH(C30,'Monthly Data'!$D$5:$D$121,0)) -> 44682 | C30: =SMALL('Monthly Data'!$D$5:$D$121,A30) -> -39993 | D30: =INDEX('Monthly Data'!$E$5:$E$121,MATCH(C30,'Monthly Data'!$D$5:$D$121,0)) -> 50835.5 | E30: =D30/-C30 -> 1.2711099 | F30: =IF(D30>=-C30,"Yes","No") -> Yes | G30: =INDEX('Monthly Data'!$K$5:$K$121,MATCH(C30,'Monthly Data'!$D$5:$D$121,0)) -> -0.030287881 | H30: =INDEX('Monthly Data'!$L$5:$L$121,MATCH(C30,'Monthly Data'!$D$5:$D$121,0)) -> 12286
A31: 10 | B31: =INDEX('Monthly Data'!$A$5:$A$121,MATCH(C31,'Monthly Data'!$D$5:$D$121,0)) -> 46023 | C31: =SMALL('Monthly Data'!$D$5:$D$121,A31) -> -35962 | D31: =INDEX('Monthly Data'!$E$5:$E$121,MATCH(C31,'Monthly Data'!$D$5:$D$121,0)) -> 69220.7 | E31: =D31/-C31 -> 1.924829 | F31: =IF(D31>=-C31,"Yes","No") -> Yes | G31: =INDEX('Monthly Data'!$K$5:$K$121,MATCH(C31,'Monthly Data'!$D$5:$D$121,0)) -> -0.030959142 | H31: =INDEX('Monthly Data'!$L$5:$L$121,MATCH(C31,'Monthly Data'!$D$5:$D$121,0)) -> 31002
A34: Group | B34: Selling months | C34: Fully offset | D34: Offset rate | E34: Avg FPI (₹ cr) | F34: Avg DII (₹ cr) | G34: Mean Nifty return
A35: 10 largest FPI-selling months | B35: 10 | C35: =COUNTIF(F22:F31,"Yes") -> 6 | D35: =C35/B35 -> 0.6 | E35: =AVERAGE(C22:C31) -> -62926 | F35: =AVERAGE(D22:D31) -> 73559.85 | G35: =AVERAGE(G22:G31) -> -0.039520008
A36: All other FPI-selling months | B36: =B6-B35 -> 43 | C36: =B7-C35 -> 36 | D36: =C36/B36 -> 0.8372093 | E36: =(SUMIFS('Monthly Data'!$D$5:$D$121,'Monthly Data'!$G$5:$G$121,"Yes")-SUM(C22:C31))/B36 -> -15658.791 | F36: =(SUMIFS('Monthly Data'!$E$5:$E$121,'Monthly Data'!$G$5:$G$121,"Yes")-SUM(D22:D31))/B36 -> 30591.693 | G36: =(SUMIFS('Monthly Data'!$K$5:$K$121,'Monthly Data'!$G$5:$G$121,"Yes")-SUM(G22:G31))/(COUNTIFS('Monthly Data'!$G$5:$G$121,"Yes",'Monthly Data'!$K$5:$K$121,">-1")-10) -> -0.0039378696
A38: The ten-month group is small, so these averages are indicative only. Months are ranked by FPI flow; ties are not present in the data.

Sheet Correlations
A1: Correlation tests
A2: Pearson r is calculated live from Monthly Data. Spearman and the robustness checks were run in Python on the same data and are stored as values. All figures describe association, not cause.
A4: 1. Institutional flows and Nifty return (same month)
A5: Flow series | B5: Months (n) | C5: Pearson r | D5: Spearman ρ
A6: FPI net flow | B6: =SUMPRODUCT(--ISNUMBER('Monthly Data'!$D$5:$D$121),--ISNUMBER('Monthly Data'!$K$5:$K$121)) -> 116 | C6: =CORREL('Monthly Data'!$D$5:$D$121,'Monthly Data'!$K$5:$K$121) -> 0.53073101 | D6: 0.5011
A7: DII net flow | B7: =SUMPRODUCT(--ISNUMBER('Monthly Data'!$E$5:$E$121),--ISNUMBER('Monthly Data'!$K$5:$K$121)) -> 116 | C7: =CORREL('Monthly Data'!$E$5:$E$121,'Monthly Data'!$K$5:$K$121) -> -0.46724052 | D7: -0.4486
A8: FPI + DII combined | B8: =SUMPRODUCT(--ISNUMBER('Monthly Data'!$F$5:$F$121),--ISNUMBER('Monthly Data'!$K$5:$K$121)) -> 116 | C8: =CORREL('Monthly Data'!$F$5:$F$121,'Monthly Data'!$K$5:$K$121) -> 0.073524191 | D8: 0.064
A10: 2. Macro indicators
A11: Indicator | B11: Compared with | C11: Months (n) | D11: Pearson r | E11: Spearman ρ
A12: USD/INR monthly change | B12: Nifty return | C12: =SUMPRODUCT(--ISNUMBER('Monthly Data'!$O$5:$O$121),--ISNUMBER('Monthly Data'!$K$5:$K$121)) -> 107 | D12: =CORREL('Monthly Data'!$O$5:$O$121,'Monthly Data'!$K$5:$K$121) -> -0.51639924 | E12: -0.487
A13: USD/INR monthly change | B13: FPI net flow | C13: =SUMPRODUCT(--ISNUMBER('Monthly Data'!$O$5:$O$121),--ISNUMBER('Monthly Data'!$D$5:$D$121)) -> 107 | D13: =CORREL('Monthly Data'!$O$5:$O$121,'Monthly Data'!$D$5:$D$121) -> -0.35836188 | E13: -0.346
A14: USD/INR monthly change | B14: DII net flow | C14: =SUMPRODUCT(--ISNUMBER('Monthly Data'!$O$5:$O$121),--ISNUMBER('Monthly Data'!$E$5:$E$121)) -> 107 | D14: =CORREL('Monthly Data'!$O$5:$O$121,'Monthly Data'!$E$5:$E$121) -> 0.27830178 | E14: 0.269
A15: Repo rate | B15: Nifty return | C15: =SUMPRODUCT(--ISNUMBER('Monthly Data'!$Q$5:$Q$121),--ISNUMBER('Monthly Data'!$K$5:$K$121)) -> 108 | D15: =CORREL('Monthly Data'!$Q$5:$Q$121,'Monthly Data'!$K$5:$K$121) -> -0.061899374 | E15: -0.04
A16: Repo rate | B16: FPI net flow | C16: =SUMPRODUCT(--ISNUMBER('Monthly Data'!$Q$5:$Q$121),--ISNUMBER('Monthly Data'!$D$5:$D$121)) -> 108 | D16: =CORREL('Monthly Data'!$Q$5:$Q$121,'Monthly Data'!$D$5:$D$121) -> 0.042127075 | E16: 0.062
A17: Repo rate | B17: DII net flow | C17: =SUMPRODUCT(--ISNUMBER('Monthly Data'!$Q$5:$Q$121),--ISNUMBER('Monthly Data'!$E$5:$E$121)) -> 108 | D17: =CORREL('Monthly Data'!$Q$5:$Q$121,'Monthly Data'!$E$5:$E$121) -> 0.17210346 | E17: 0.168
A18: CPI inflation (YoY) | B18: Nifty return | C18: =SUMPRODUCT(--ISNUMBER('Monthly Data'!$P$5:$P$121),--ISNUMBER('Monthly Data'!$K$5:$K$121)) -> 116 | D18: =CORREL('Monthly Data'!$P$5:$P$121,'Monthly Data'!$K$5:$K$121) -> 0.025343519 | E18: 0.013
A19: CPI inflation (YoY) | B19: FPI net flow | C19: =SUMPRODUCT(--ISNUMBER('Monthly Data'!$P$5:$P$121),--ISNUMBER('Monthly Data'!$D$5:$D$121)) -> 117 | D19: =CORREL('Monthly Data'!$P$5:$P$121,'Monthly Data'!$D$5:$D$121) -> 0.074409529 | E19: 0.057
A20: CPI inflation (YoY) | B20: DII net flow | C20: =SUMPRODUCT(--ISNUMBER('Monthly Data'!$P$5:$P$121),--ISNUMBER('Monthly Data'!$E$5:$E$121)) -> 117 | D20: =CORREL('Monthly Data'!$P$5:$P$121,'Monthly Data'!$E$5:$E$121) -> -0.26450285 | E20: -0.183
A22: 3. Robustness of the USD/INR and Nifty relationship (stored values)
A23: Test | B23: Months (n) | C23: Pearson r | D23: Spearman ρ
A24: All complete months | B24: 107 | C24: -0.516 | D24: -0.487
A25: Excluding outer 2.5% tails of both variables | B25: 97 | C25: -0.37 | D25: -0.4
A26: 2017 to 2019 | B26: 26 | C26: -0.388 | D26: -0.318
A27: 2020 to 2023 | B27: 48 | C27: -0.657 | D27: -0.588
A28: 2024 to Sep 2026 | B28: 33 | C28: -0.611 | D28: -0.431
A30: 4. SIP and offsetting (stored values, FPI-selling months only, n = 53)
A31: SIP level vs fully-offset indicator | C31: 0.255
A32: SIP level vs offset ratio | C32: -0.041
A34: Reading the table: a negative r between USD/INR change and Nifty return means months of larger rupee depreciation tended to be months of weaker equity returns.

Sheet Annual Summary
A1: Annual summary
A2: Calculated from Monthly Data. 2026 covers January to September (nine complete months).
A4: Year | B4: Months | C4: FPI net flow (₹ cr) | D4: DII net flow (₹ cr) | E4: FPI-selling months | F4: Fully offset | G4: Avg monthly Nifty return | H4: SIP total (₹ cr) | I4: Avg monthly SIP (₹ cr)
A5: 2017 | B5: =COUNTIF('Monthly Data'!$B$5:$B$121,A5) -> 12 | C5: =SUMIFS('Monthly Data'!$D$5:$D$121,'Monthly Data'!$B$5:$B$121,A5) -> 51252 | D5: =SUMIFS('Monthly Data'!$E$5:$E$121,'Monthly Data'!$B$5:$B$121,A5) -> 90738.3 | E5: =COUNTIFS('Monthly Data'!$B$5:$B$121,A5,'Monthly Data'!$G$5:$G$121,"Yes") -> 4 | F5: =COUNTIFS('Monthly Data'!$B$5:$B$121,A5,'Monthly Data'!$H$5:$H$121,"Yes") -> 4 | G5: =AVERAGEIFS('Monthly Data'!$K$5:$K$121,'Monthly Data'!$B$5:$B$121,A5) -> 0.019347724 | H5: =SUMIFS('Monthly Data'!$L$5:$L$121,'Monthly Data'!$B$5:$B$121,A5) -> 59482 | I5: =H5/B5 -> 4956.8333
A6: 2018 | B6: =COUNTIF('Monthly Data'!$B$5:$B$121,A6) -> 12 | C6: =SUMIFS('Monthly Data'!$D$5:$D$121,'Monthly Data'!$B$5:$B$121,A6) -> -33014 | D6: =SUMIFS('Monthly Data'!$E$5:$E$121,'Monthly Data'!$B$5:$B$121,A6) -> 109661.8 | E6: =COUNTIFS('Monthly Data'!$B$5:$B$121,A6,'Monthly Data'!$G$5:$G$121,"Yes") -> 6 | F6: =COUNTIFS('Monthly Data'!$B$5:$B$121,A6,'Monthly Data'!$H$5:$H$121,"Yes") -> 5 | G6: =AVERAGEIFS('Monthly Data'!$K$5:$K$121,'Monthly Data'!$B$5:$B$121,A6) -> 0.0035394434 | H6: =SUMIFS('Monthly Data'!$L$5:$L$121,'Monthly Data'!$B$5:$B$121,A6) -> 88667 | I6: =H6/B6 -> 7388.9167
A7: 2019 | B7: =COUNTIF('Monthly Data'!$B$5:$B$121,A7) -> 12 | C7: =SUMIFS('Monthly Data'!$D$5:$D$121,'Monthly Data'!$B$5:$B$121,A7) -> 101122 | D7: =SUMIFS('Monthly Data'!$E$5:$E$121,'Monthly Data'!$B$5:$B$121,A7) -> 42257.2 | E7: =COUNTIFS('Monthly Data'!$B$5:$B$121,A7,'Monthly Data'!$G$5:$G$121,"Yes") -> 3 | F7: =COUNTIFS('Monthly Data'!$B$5:$B$121,A7,'Monthly Data'!$H$5:$H$121,"Yes") -> 2 | G7: =AVERAGEIFS('Monthly Data'!$K$5:$K$121,'Monthly Data'!$B$5:$B$121,A7) -> 0.0099901648 | H7: =SUMIFS('Monthly Data'!$L$5:$L$121,'Monthly Data'!$B$5:$B$121,A7) -> 98612 | I7: =H7/B7 -> 8217.6667
A8: 2020 | B8: =COUNTIF('Monthly Data'!$B$5:$B$121,A8) -> 12 | C8: =SUMIFS('Monthly Data'!$D$5:$D$121,'Monthly Data'!$B$5:$B$121,A8) -> 170262 | D8: =SUMIFS('Monthly Data'!$E$5:$E$121,'Monthly Data'!$B$5:$B$121,A8) -> -35663.2 | E8: =COUNTIFS('Monthly Data'!$B$5:$B$121,A8,'Monthly Data'!$G$5:$G$121,"Yes") -> 3 | F8: =COUNTIFS('Monthly Data'!$B$5:$B$121,A8,'Monthly Data'!$H$5:$H$121,"Yes") -> 0 | G8: =AVERAGEIFS('Monthly Data'!$K$5:$K$121,'Monthly Data'!$B$5:$B$121,A8) -> 0.016573749 | H8: =SUMIFS('Monthly Data'!$L$5:$L$121,'Monthly Data'!$B$5:$B$121,A8) -> 97033 | I8: =H8/B8 -> 8086.0833
A9: 2021 | B9: =COUNTIF('Monthly Data'!$B$5:$B$121,A9) -> 12 | C9: =SUMIFS('Monthly Data'!$D$5:$D$121,'Monthly Data'!$B$5:$B$121,A9) -> 25752 | D9: =SUMIFS('Monthly Data'!$E$5:$E$121,'Monthly Data'!$B$5:$B$121,A9) -> 95074.8 | E9: =COUNTIFS('Monthly Data'!$B$5:$B$121,A9,'Monthly Data'!$G$5:$G$121,"Yes") -> 6 | F9: =COUNTIFS('Monthly Data'!$B$5:$B$121,A9,'Monthly Data'!$H$5:$H$121,"Yes") -> 4 | G9: =AVERAGEIFS('Monthly Data'!$K$5:$K$121,'Monthly Data'!$B$5:$B$121,A9) -> 0.018797509 | H9: =SUMIFS('Monthly Data'!$L$5:$L$121,'Monthly Data'!$B$5:$B$121,A9) -> 114016 | I9: =H9/B9 -> 9501.3333
A10: 2022 | B10: =COUNTIF('Monthly Data'!$B$5:$B$121,A10) -> 12 | C10: =SUMIFS('Monthly Data'!$D$5:$D$121,'Monthly Data'!$B$5:$B$121,A10) -> -121439 | D10: =SUMIFS('Monthly Data'!$E$5:$E$121,'Monthly Data'!$B$5:$B$121,A10) -> 276698.7 | E10: =COUNTIFS('Monthly Data'!$B$5:$B$121,A10,'Monthly Data'!$G$5:$G$121,"Yes") -> 8 | F10: =COUNTIFS('Monthly Data'!$B$5:$B$121,A10,'Monthly Data'!$H$5:$H$121,"Yes") -> 5 | G10: =AVERAGEIFS('Monthly Data'!$K$5:$K$121,'Monthly Data'!$B$5:$B$121,A10) -> 0.0044445514 | H10: =SUMIFS('Monthly Data'!$L$5:$L$121,'Monthly Data'!$B$5:$B$121,A10) -> 149437 | I10: =H10/B10 -> 12453.083
A11: 2023 | B11: =COUNTIF('Monthly Data'!$B$5:$B$121,A11) -> 12 | C11: =SUMIFS('Monthly Data'!$D$5:$D$121,'Monthly Data'!$B$5:$B$121,A11) -> 171107 | D11: =SUMIFS('Monthly Data'!$E$5:$E$121,'Monthly Data'!$B$5:$B$121,A11) -> 184650.1 | E11: =COUNTIFS('Monthly Data'!$B$5:$B$121,A11,'Monthly Data'!$G$5:$G$121,"Yes") -> 4 | F11: =COUNTIFS('Monthly Data'!$B$5:$B$121,A11,'Monthly Data'!$H$5:$H$121,"Yes") -> 4 | G11: =AVERAGEIFS('Monthly Data'!$K$5:$K$121,'Monthly Data'!$B$5:$B$121,A11) -> 0.015886719 | H11: =SUMIFS('Monthly Data'!$L$5:$L$121,'Monthly Data'!$B$5:$B$121,A11) -> 183741 | I11: =H11/B11 -> 15311.75
A12: 2024 | B12: =COUNTIF('Monthly Data'!$B$5:$B$121,A12) -> 12 | C12: =SUMIFS('Monthly Data'!$D$5:$D$121,'Monthly Data'!$B$5:$B$121,A12) -> 427 | D12: =SUMIFS('Monthly Data'!$E$5:$E$121,'Monthly Data'!$B$5:$B$121,A12) -> 526545.1 | E12: =COUNTIFS('Monthly Data'!$B$5:$B$121,A12,'Monthly Data'!$G$5:$G$121,"Yes") -> 5 | F12: =COUNTIFS('Monthly Data'!$B$5:$B$121,A12,'Monthly Data'!$H$5:$H$121,"Yes") -> 5 | G12: =AVERAGEIFS('Monthly Data'!$K$5:$K$121,'Monthly Data'!$B$5:$B$121,A12) -> 0.0075018727 | H12: =SUMIFS('Monthly Data'!$L$5:$L$121,'Monthly Data'!$B$5:$B$121,A12) -> 268323 | I12: =H12/B12 -> 22360.25
A13: 2025 | B13: =COUNTIF('Monthly Data'!$B$5:$B$121,A13) -> 12 | C13: =SUMIFS('Monthly Data'!$D$5:$D$121,'Monthly Data'!$B$5:$B$121,A13) -> -166286 | D13: =SUMIFS('Monthly Data'!$E$5:$E$121,'Monthly Data'!$B$5:$B$121,A13) -> 788184.4 | E13: =COUNTIFS('Monthly Data'!$B$5:$B$121,A13,'Monthly Data'!$G$5:$G$121,"Yes") -> 8 | F13: =COUNTIFS('Monthly Data'!$B$5:$B$121,A13,'Monthly Data'!$H$5:$H$121,"Yes") -> 8 | G13: =AVERAGEIFS('Monthly Data'!$K$5:$K$121,'Monthly Data'!$B$5:$B$121,A13) -> 0.0088819056 | H13: =SUMIFS('Monthly Data'!$L$5:$L$121,'Monthly Data'!$B$5:$B$121,A13) -> 334980 | I13: =H13/B13 -> 27915
A14: 2026 | B14: =COUNTIF('Monthly Data'!$B$5:$B$121,A14) -> 9 | C14: =SUMIFS('Monthly Data'!$D$5:$D$121,'Monthly Data'!$B$5:$B$121,A14) -> -260302 | D14: =SUMIFS('Monthly Data'!$E$5:$E$121,'Monthly Data'!$B$5:$B$121,A14) -> 639534.8 | E14: =COUNTIFS('Monthly Data'!$B$5:$B$121,A14,'Monthly Data'!$G$5:$G$121,"Yes") -> 6 | F14: =COUNTIFS('Monthly Data'!$B$5:$B$121,A14,'Monthly Data'!$H$5:$H$121,"Yes") -> 5 | G14: =AVERAGEIFS('Monthly Data'!$K$5:$K$121,'Monthly Data'!$B$5:$B$121,A14) -> -0.014626924 | H14: =SUMIFS('Monthly Data'!$L$5:$L$121,'Monthly Data'!$B$5:$B$121,A14) -> 283532 | I14: =H14/B14 -> 31503.556
A15: Total | B15: =SUM(B5:B14) -> 117 | C15: =SUM(C5:C14) -> -61119 | D15: =SUM(D5:D14) -> 2717682 | E15: =SUM(E5:E14) -> 53 | F15: =SUM(F5:F14) -> 42 | H15: =SUM(H5:H14) -> 1677823

Sheet Monthly Data
A1: Monthly dataset, January 2017 to October 2026
A2: Blue = source data entered as values; black = calculated. Analysis uses complete months only (rows 5 to 121). October 2026 (row 122) is partial, to 23 Oct, and is shown for reference.
A4: Month | B4: Year | C4: Status | D4: FPI net flow (₹ cr) | E4: DII net flow (₹ cr) | F4: FPI + DII (₹ cr) | G4: FPI selling? | H4: DII fully offsets? | I4: Offset ratio (DII ÷ FPI selling) | J4: Nifty 50 close | K4: Nifty monthly return | L4: SIP contribution (₹ cr) | M4: Equity MF AUM (₹ cr, quarter-end) | N4: USD/INR (month-end) | O4: USD/INR monthly change | P4: CPI inflation (YoY, %) | Q4: Repo rate (%)
A5: 42736 | B5: =YEAR(A5) -> 2017 | C5: Complete | D5: -1177 | E5: 4503.9 | F5: =D5+E5 -> 3326.9 | G5: =IF(D5<0,"Yes","No") -> Yes | H5: =IF(D5<0,IF(E5>=-D5,"Yes","No"),"n/a") -> Yes | I5: =IF(D5<0,E5/-D5,"") -> 3.826593 | J5: 8561.3 | L5: 4095 | P5: 3.2
A6: 42767 | B6: =YEAR(A6) -> 2017 | C6: Complete | D6: 9902 | E6: 935.3 | F6: =D6+E6 -> 10837.3 | G6: =IF(D6<0,"Yes","No") -> No | H6: =IF(D6<0,IF(E6>=-D6,"Yes","No"),"n/a") -> n/a | I6: =IF(D6<0,E6/-D6,"") | J6: 8879.6 | K6: =J6/J5-1 -> 0.037178933 | L6: 4050 | P6: 3.7
A7: 42795 | B7: =YEAR(A7) -> 2017 | C7: Complete | D7: 30906 | E7: -4395.6 | F7: =D7+E7 -> 26510.4 | G7: =IF(D7<0,"Yes","No") -> No | H7: =IF(D7<0,IF(E7>=-D7,"Yes","No"),"n/a") -> n/a | I7: =IF(D7<0,E7/-D7,"") | J7: 9173.75 | K7: =J7/J6-1 -> 0.033126492 | L7: 4335 | M7: 543541.22 | P7: 3.9
A8: 42826 | B8: =YEAR(A8) -> 2017 | C8: Complete | D8: 2394 | E8: 9247.4 | F8: =D8+E8 -> 11641.4 | G8: =IF(D8<0,"Yes","No") -> No | H8: =IF(D8<0,IF(E8>=-D8,"Yes","No"),"n/a") -> n/a | I8: =IF(D8<0,E8/-D8,"") | J8: 9304.05 | K8: =J8/J7-1 -> 0.01420357 | L8: 4269 | P8: 3
A9: 42856 | B9: =YEAR(A9) -> 2017 | C9: Complete | D9: 7711 | E9: 4277.1 | F9: =D9+E9 -> 11988.1 | G9: =IF(D9<0,"Yes","No") -> No | H9: =IF(D9<0,IF(E9>=-D9,"Yes","No"),"n/a") -> n/a | I9: =IF(D9<0,E9/-D9,"") | J9: 9621.25 | K9: =J9/J8-1 -> 0.03409268 | L9: 4584 | P9: 2.2
A10: 42887 | B10: =YEAR(A10) -> 2017 | C10: Complete | D10: 3617 | E10: 6676.1 | F10: =D10+E10 -> 10293.1 | G10: =IF(D10<0,"Yes","No") -> No | H10: =IF(D10<0,IF(E10>=-D10,"Yes","No"),"n/a") -> n/a | I10: =IF(D10<0,E10/-D10,"") | J10: 9520.9 | K10: =J10/J9-1 -> -0.010430038 | L10: 4744 | M10: 591376.9 | P10: 1.5
A11: 42917 | B11: =YEAR(A11) -> 2017 | C11: Complete | D11: 5161 | E11: 4786.4 | F11: =D11+E11 -> 9947.4 | G11: =IF(D11<0,"Yes","No") -> No | H11: =IF(D11<0,IF(E11>=-D11,"Yes","No"),"n/a") -> n/a | I11: =IF(D11<0,E11/-D11,"") | J11: 10077.1 | K11: =J11/J10-1 -> 0.058418847 | L11: 4947 | P11: 2.4
A12: 42948 | B12: =YEAR(A12) -> 2017 | C12: Complete | D12: -12770 | E12: 16205.2 | F12: =D12+E12 -> 3435.2 | G12: =IF(D12<0,"Yes","No") -> Yes | H12: =IF(D12<0,IF(E12>=-D12,"Yes","No"),"n/a") -> Yes | I12: =IF(D12<0,E12/-D12,"") -> 1.2690055 | J12: 9917.9 | K12: =J12/J11-1 -> -0.015798196 | L12: 5206 | P12: 3.3
A13: 42979 | B13: =YEAR(A13) -> 2017 | C13: Complete | D13: -11392 | E13: 21025.5 | F13: =D13+E13 -> 9633.5 | G13: =IF(D13<0,"Yes","No") -> Yes | H13: =IF(D13<0,IF(E13>=-D13,"Yes","No"),"n/a") -> Yes | I13: =IF(D13<0,E13/-D13,"") -> 1.8456373 | J13: 9788.6 | K13: =J13/J12-1 -> -0.013037034 | L13: 5516 | M13: 659182.64 | P13: 3.3
A14: 43009 | B14: =YEAR(A14) -> 2017 | C14: Complete | D14: 3055 | E14: 10090.9 | F14: =D14+E14 -> 13145.9 | G14: =IF(D14<0,"Yes","No") -> No | H14: =IF(D14<0,IF(E14>=-D14,"Yes","No"),"n/a") -> n/a | I14: =IF(D14<0,E14/-D14,"") | J14: 10335.3 | K14: =J14/J13-1 -> 0.055850683 | L14: 5621 | N14: 64.7745 | P14: 3.6 | Q14: 6
A15: 43040 | B15: =YEAR(A15) -> 2017 | C15: Complete | D15: 19728 | E15: 9243.2 | F15: =D15+E15 -> 28971.2 | G15: =IF(D15<0,"Yes","No") -> No | H15: =IF(D15<0,IF(E15>=-D15,"Yes","No"),"n/a") -> n/a | I15: =IF(D15<0,E15/-D15,"") | J15: 10226.55 | K15: =J15/J14-1 -> -0.010522191 | L15: 5893 | N15: 64.4332 | O15: =N15/N14-1 -> -0.0052690488 | P15: 4.9 | Q15: 6
A16: 43070 | B16: =YEAR(A16) -> 2017 | C16: Complete | D16: -5883 | E16: 8142.9 | F16: =D16+E16 -> 2259.9 | G16: =IF(D16<0,"Yes","No") -> Yes | H16: =IF(D16<0,IF(E16>=-D16,"Yes","No"),"n/a") -> Yes | I16: =IF(D16<0,E16/-D16,"") -> 1.3841407 | J16: 10530.7 | K16: =J16/J15-1 -> 0.029741213 | L16: 6222 | M16: 771134.5 | N16: 63.9273 | O16: =N16/N15-1 -> -0.0078515424 | P16: 5.2 | Q16: 6
A17: 43101 | B17: =YEAR(A17) -> 2018 | C17: Complete | D17: 13781 | E17: 398.7 | F17: =D17+E17 -> 14179.7 | G17: =IF(D17<0,"Yes","No") -> No | H17: =IF(D17<0,IF(E17>=-D17,"Yes","No"),"n/a") -> n/a | I17: =IF(D17<0,E17/-D17,"") | J17: 11027.7 | K17: =J17/J16-1 -> 0.047195343 | L17: 6644 | N17: 63.6878 | O17: =N17/N16-1 -> -0.0037464432 | P17: 5.1 | Q17: 6
A18: 43132 | B18: =YEAR(A18) -> 2018 | C18: Complete | D18: -11423 | E18: 17813 | F18: =D18+E18 -> 6390 | G18: =IF(D18<0,"Yes","No") -> Yes | H18: =IF(D18<0,IF(E18>=-D18,"Yes","No"),"n/a") -> Yes | I18: =IF(D18<0,E18/-D18,"") -> 1.5593977 | J18: 10492.85 | K18: =J18/J17-1 -> -0.048500594 | L18: 6425 | N18: 65.1031 | O18: =N18/N17-1 -> 0.022222466 | P18: 4.4 | Q18: 6
A19: 43160 | B19: =YEAR(A19) -> 2018 | C19: Complete | D19: 11654 | E19: 6693.9 | F19: =D19+E19 -> 18347.9 | G19: =IF(D19<0,"Yes","No") -> No | H19: =IF(D19<0,IF(E19>=-D19,"Yes","No"),"n/a") -> n/a | I19: =IF(D19<0,E19/-D19,"") | J19: 10113.7 | K19: =J19/J18-1 -> -0.036134129 | L19: 7119 | M19: 749789.68 | N19: 65.0441 | O19: =N19/N18-1 -> -0.00090625485 | P19: 4.3 | Q19: 6
A20: 43191 | B20: =YEAR(A20) -> 2018 | C20: Complete | D20: -5552 | E20: 8663.9 | F20: =D20+E20 -> 3111.9 | G20: =IF(D20<0,"Yes","No") -> Yes | H20: =IF(D20<0,IF(E20>=-D20,"Yes","No"),"n/a") -> Yes | I20: =IF(D20<0,E20/-D20,"") -> 1.5605007 | J20: 10739.35 | K20: =J20/J19-1 -> 0.061861633 | L20: 6690 | N20: 66.7801 | O20: =N20/N19-1 -> 0.026689584 | P20: 4.6 | Q20: 6
A21: 43221 | B21: =YEAR(A21) -> 2018 | C21: Complete | D21: -10060 | E21: 15054.5 | F21: =D21+E21 -> 4994.5 | G21: =IF(D21<0,"Yes","No") -> Yes | H21: =IF(D21<0,IF(E21>=-D21,"Yes","No"),"n/a") -> Yes | I21: =IF(D21<0,E21/-D21,"") -> 1.4964712 | J21: 10736.15 | K21: =J21/J20-1 -> -0.00029796962 | L21: 7304 | N21: 67.4526 | O21: =N21/N20-1 -> 0.010070365 | P21: 4.9 | Q21: 6
A22: 43252 | B22: =YEAR(A22) -> 2018 | C22: Complete | D22: -4831 | E22: 14146.2 | F22: =D22+E22 -> 9315.2 | G22: =IF(D22<0,"Yes","No") -> Yes | H22: =IF(D22<0,IF(E22>=-D22,"Yes","No"),"n/a") -> Yes | I22: =IF(D22<0,E22/-D22,"") -> 2.9282136 | J22: 10714.3 | K22: =J22/J21-1 -> -0.0020351802 | L22: 7554 | M22: 786591.17 | N22: 68.5753 | O22: =N22/N21-1 -> 0.016644281 | P22: 4.9 | Q22: 6.25
A23: 43282 | B23: =YEAR(A23) -> 2018 | C23: Complete | D23: 2264 | E23: 3845.9 | F23: =D23+E23 -> 6109.9 | G23: =IF(D23<0,"Yes","No") -> No | H23: =IF(D23<0,IF(E23>=-D23,"Yes","No"),"n/a") -> n/a | I23: =IF(D23<0,E23/-D23,"") | J23: 11356.5 | K23: =J23/J22-1 -> 0.059938587 | L23: 7554 | N23: 68.6068 | O23: =N23/N22-1 -> 0.00045934907 | P23: 4.2 | Q23: 6.25
A24: 43313 | B24: =YEAR(A24) -> 2018 | C24: Complete | D24: 1775 | E24: 2822.7 | F24: =D24+E24 -> 4597.7 | G24: =IF(D24<0,"Yes","No") -> No | H24: =IF(D24<0,IF(E24>=-D24,"Yes","No"),"n/a") -> n/a | I24: =IF(D24<0,E24/-D24,"") | J24: 11680.5 | K24: =J24/J23-1 -> 0.028529917 | L24: 7658 | N24: 70.9255 | O24: =N24/N23-1 -> 0.033796941 | P24: 3.7 | Q24: 6.5
A25: 43344 | B25: =YEAR(A25) -> 2018 | C25: Complete | D25: -10825 | E25: 12504 | F25: =D25+E25 -> 1679 | G25: =IF(D25<0,"Yes","No") -> Yes | H25: =IF(D25<0,IF(E25>=-D25,"Yes","No"),"n/a") -> Yes | I25: =IF(D25<0,E25/-D25,"") -> 1.1551039 | J25: 10930.45 | K25: =J25/J24-1 -> -0.064213861 | L25: 7727 | M25: 802215.26 | N25: 72.5474 | O25: =N25/N24-1 -> 0.022867657 | P25: 3.7 | Q25: 6.5
A26: 43374 | B26: =YEAR(A26) -> 2018 | C26: Complete | D26: -28921 | E26: 26033.9 | F26: =D26+E26 -> -2887.1 | G26: =IF(D26<0,"Yes","No") -> Yes | H26: =IF(D26<0,IF(E26>=-D26,"Yes","No"),"n/a") -> No | I26: =IF(D26<0,E26/-D26,"") -> 0.90017288 | J26: 10386.6 | K26: =J26/J25-1 -> -0.0497555 | L26: 7985 | N26: 73.9936 | O26: =N26/N25-1 -> 0.019934553 | P26: 3.38 | Q26: 6.5
A27: 43405 | B27: =YEAR(A27) -> 2018 | C27: Complete | D27: 5981 | E27: 1309.5 | F27: =D27+E27 -> 7290.5 | G27: =IF(D27<0,"Yes","No") -> No | H27: =IF(D27<0,IF(E27>=-D27,"Yes","No"),"n/a") -> n/a | I27: =IF(D27<0,E27/-D27,"") | J27: 10876.75 | K27: =J27/J26-1 -> 0.047190611 | L27: 7985 | N27: 69.6574 | O27: =N27/N26-1 -> -0.058602366 | P27: 2.33 | Q27: 6.5
A28: 43435 | B28: =YEAR(A28) -> 2018 | C28: Complete | D28: 3143 | E28: 375.6 | F28: =D28+E28 -> 3518.6 | G28: =IF(D28<0,"Yes","No") -> No | H28: =IF(D28<0,IF(E28>=-D28,"Yes","No"),"n/a") -> n/a | I28: =IF(D28<0,E28/-D28,"") | J28: 10862.55 | K28: =J28/J27-1 -> -0.001305537 | L28: 8022 | M28: 844054.16 | N28: 69.7923 | O28: =N28/N27-1 -> 0.0019366212 | P28: 2.11 | Q28: 6.5
A29: 43466 | B29: =YEAR(A29) -> 2019 | C29: Complete | D29: -4262 | E29: 2146.9 | F29: =D29+E29 -> -2115.1 | G29: =IF(D29<0,"Yes","No") -> Yes | H29: =IF(D29<0,IF(E29>=-D29,"Yes","No"),"n/a") -> No | I29: =IF(D29<0,E29/-D29,"") -> 0.50373064 | J29: 10830.95 | K29: =J29/J28-1 -> -0.0029090775 | L29: 8064 | N29: 71.0333 | O29: =N29/N28-1 -> 0.017781331 | P29: 1.97 | Q29: 6.5
A30: 43497 | B30: =YEAR(A30) -> 2019 | C30: Complete | D30: 17220 | E30: -565.9 | F30: =D30+E30 -> 16654.1 | G30: =IF(D30<0,"Yes","No") -> No | H30: =IF(D30<0,IF(E30>=-D30,"Yes","No"),"n/a") -> n/a | I30: =IF(D30<0,E30/-D30,"") | J30: 10792.5 | K30: =J30/J29-1 -> -0.0035500118 | L30: 8095 | N30: 71.1953 | O30: =N30/N29-1 -> 0.0022806205 | P30: 2.57 | Q30: 6.25
A31: 43525 | B31: =YEAR(A31) -> 2019 | C31: Complete | D31: 33981 | E31: -13930.2 | F31: =D31+E31 -> 20050.8 | G31: =IF(D31<0,"Yes","No") -> No | H31: =IF(D31<0,IF(E31>=-D31,"Yes","No"),"n/a") -> n/a | I31: =IF(D31<0,E31/-D31,"") | J31: 11623.9 | K31: =J31/J30-1 -> 0.077034978 | L31: 8055 | M31: 892101.03 | N31: 69.1713 | O31: =N31/N30-1 -> -0.028428843 | P31: 2.86 | Q31: 6.25
A32: 43556 | B32: =YEAR(A32) -> 2019 | C32: Complete | D32: 21193 | E32: -4219.5 | F32: =D32+E32 -> 16973.5 | G32: =IF(D32<0,"Yes","No") -> No | H32: =IF(D32<0,IF(E32>=-D32,"Yes","No"),"n/a") -> n/a | I32: =IF(D32<0,E32/-D32,"") | J32: 11748.15 | K32: =J32/J31-1 -> 0.010689183 | L32: 8238 | N32: 69.8368 | O32: =N32/N31-1 -> 0.0096210423 | P32: 2.99 | Q32: 6
A33: 43586 | B33: =YEAR(A33) -> 2019 | C33: Complete | D33: 7920 | E33: 5316.3 | F33: =D33+E33 -> 13236.3 | G33: =IF(D33<0,"Yes","No") -> No | H33: =IF(D33<0,IF(E33>=-D33,"Yes","No"),"n/a") -> n/a | I33: =IF(D33<0,E33/-D33,"") | J33: 11922.8 | K33: =J33/J32-1 -> 0.01486617 | L33: 8183 | N33: 69.8058 | O33: =N33/N32-1 -> -0.00044389205 | P33: 3.05 | Q33: 6
A34: 43617 | B34: =YEAR(A34) -> 2019 | C34: Complete | D34: 2596 | E34: 3643.3 | F34: =D34+E34 -> 6239.3 | G34: =IF(D34<0,"Yes","No") -> No | H34: =IF(D34<0,IF(E34>=-D34,"Yes","No"),"n/a") -> n/a | I34: =IF(D34<0,E34/-D34,"") | J34: 11788.85 | K34: =J34/J33-1 -> -0.011234777 | L34: 8122 | M34: 760189.57 | N34: 68.918 | O34: =N34/N33-1 -> -0.012718141 | P34: 3.18 | Q34: 5.75
A35: 43647 | B35: =YEAR(A35) -> 2019 | C35: Complete | D35: -12419 | E35: 20394.5 | F35: =D35+E35 -> 7975.5 | G35: =IF(D35<0,"Yes","No") -> Yes | H35: =IF(D35<0,IF(E35>=-D35,"Yes","No"),"n/a") -> Yes | I35: =IF(D35<0,E35/-D35,"") -> 1.6422015 | J35: 11118 | K35: =J35/J34-1 -> -0.056905466 | L35: 8324 | N35: 68.8569 | O35: =N35/N34-1 -> -0.00088656084 | P35: 3.15 | Q35: 5.75
A36: 43678 | B36: =YEAR(A36) -> 2019 | C36: Complete | D36: -17592 | E36: 20933.6 | F36: =D36+E36 -> 3341.6 | G36: =IF(D36<0,"Yes","No") -> Yes | H36: =IF(D36<0,IF(E36>=-D36,"Yes","No"),"n/a") -> Yes | I36: =IF(D36<0,E36/-D36,"") -> 1.18995 | J36: 11023.25 | K36: =J36/J35-1 -> -0.0085222162 | L36: 8231 | N36: 71.7586 | O36: =N36/N35-1 -> 0.04214102 | P36: 3.28 | Q36: 5.4
A37: 43709 | B37: =YEAR(A37) -> 2019 | C37: Complete | D37: 7548 | E37: 12490.8 | F37: =D37+E37 -> 20038.8 | G37: =IF(D37<0,"Yes","No") -> No | H37: =IF(D37<0,IF(E37>=-D37,"Yes","No"),"n/a") -> n/a | I37: =IF(D37<0,E37/-D37,"") | J37: 11474.45 | K37: =J37/J36-1 -> 0.040931667 | L37: 8263 | M37: 759324.71 | N37: 70.685 | O37: =N37/N36-1 -> -0.014961273 | P37: 3.99 | Q37: 5.4
A38: 43739 | B38: =YEAR(A38) -> 2019 | C38: Complete | D38: 12368 | E38: 4758.5 | F38: =D38+E38 -> 17126.5 | G38: =IF(D38<0,"Yes","No") -> No | H38: =IF(D38<0,IF(E38>=-D38,"Yes","No"),"n/a") -> n/a | I38: =IF(D38<0,E38/-D38,"") | J38: 11877.45 | K38: =J38/J37-1 -> 0.035121509 | L38: 8246 | N38: 70.8095 | O38: =N38/N37-1 -> 0.0017613355 | P38: 4.62 | Q38: 5.15
A39: 43770 | B39: =YEAR(A39) -> 2019 | C39: Complete | D39: 25231 | E39: -7970.3 | F39: =D39+E39 -> 17260.7 | G39: =IF(D39<0,"Yes","No") -> No | H39: =IF(D39<0,IF(E39>=-D39,"Yes","No"),"n/a") -> n/a | I39: =IF(D39<0,E39/-D39,"") | J39: 12056.05 | K39: =J39/J38-1 -> 0.015036898 | L39: 8273 | N39: 71.7255 | O39: =N39/N38-1 -> 0.012936117 | P39: 5.54 | Q39: 5.15
A40: 43800 | B40: =YEAR(A40) -> 2019 | C40: Complete | D40: 7338 | E40: -740.8 | F40: =D40+E40 -> 6597.2 | G40: =IF(D40<0,"Yes","No") -> No | H40: =IF(D40<0,IF(E40>=-D40,"Yes","No"),"n/a") -> n/a | I40: =IF(D40<0,E40/-D40,"") | J40: 12168.45 | K40: =J40/J39-1 -> 0.0093231199 | L40: 8518 | M40: 805797.82 | N40: 71.274 | O40: =N40/N39-1 -> -0.0062948324 | P40: 7.35 | Q40: 5.15
A41: 43831 | B41: =YEAR(A41) -> 2020 | C41: Complete | D41: 12123 | E41: 1073.5 | F41: =D41+E41 -> 13196.5 | G41: =IF(D41<0,"Yes","No") -> No | H41: =IF(D41<0,IF(E41>=-D41,"Yes","No"),"n/a") -> n/a | I41: =IF(D41<0,E41/-D41,"") | J41: 11962.1 | K41: =J41/J40-1 -> -0.016957788 | L41: 8532 | N41: 71.5096 | O41: =N41/N40-1 -> 0.0033055532 | P41: 7.59 | Q41: 5.15
...

Sheet Method & Sources
A1: Method, sources and status
A3: Objective
A4: Question | B4: Whether domestic institutional buying has become large enough to absorb foreign portfolio selling in Indian equities, and how flows relate to Nifty returns, SIP growth and macro conditions.
A6: Definitions
A7: Flow sign | B7: Positive = net buying, negative = net selling. Monthly flow is the net equity position for the calendar month, in ₹ crore.
A8: Fully offset | B8: A month where FPI net flow is negative and DII net flow is at least equal to its absolute value.
A9: Nifty return | B9: Month-end close divided by prior month-end close, minus one.
A10: USD/INR change | B10: Month-end rate divided by prior month-end rate, minus one. A positive value is rupee depreciation.
A11: Sample | B11: 117 complete months, January 2017 to September 2026. October 2026 is partial (to 23 Oct) and excluded from all statistics.
A12: Missing data | B12: Left blank, never set to zero. Repo rate and USD/INR begin in October 2017; Nifty return begins in February 2017; AUM is available at quarter-ends only.
A14: Data sources
A15: FPI net equity flow | B15: NSDL monthly reports (depository basis).
A16: DII net equity flow | B16: Trendlyne monthly table, transcribed manually. July 2026 checked against published figures.
A17: Nifty 50 | B17: NSE daily index files, aggregated to month-end.
A18: SIP contributions | B18: AMFI monthly SIP data. December 2025 and January 2026 both report ₹31,002 crore, confirmed against AMFI.
A19: Equity mutual fund AUM | B19: AMFI quarterly category-wise report; sum of equity-oriented category totals.
A20: Repo rate, USD/INR, CPI | B20: Monthly macro indicators file compiled from RBI and MoSPI releases.
A22: Status and limitations
A23: Flow series | B23: FPI (depository basis) and DII (exchange basis) come from different sources and may not be strictly comparable. For July 2026 the FPI figure here is +₹20,200 crore against about -₹5,779 crore in the exchange cash-market data.
A24: Next step | B24: Rebuild both series from the NSE combined FII/FPI and DII cash-market report (NSE, BSE and MSEI), aggregate to months, and rerun the offset, stress-test and correlation tabs. Offset rates and flow correlations should be treated as preliminary until then.
A25: Interpretation | B25: All results are descriptive associations. No causal claim is made.
A26: Not used | B26: AMFI folio counts are excluded because category folios overlap and do not represent unique investors.
A28: Workbook map
A29: Summary | B29: Headline figures and charts.
A30: Findings | B30: Seven findings with result, reading and limitation.
A31: Offset Analysis | B31: Offset rates, regime returns and the ten-month stress test.
A32: Correlations | B32: Flow and macro correlations with robustness checks.
A33: Annual Summary | B33: Year-by-year flows, offsets and SIP.
A34: Monthly Data | B34: Source data and calculated columns that drive every other tab.
